Workbook

Sheet Sheet 1
A1: Charter | B1: DistrictName | C1: DistrictType | D1: NCESDistrictID | E1: EnrollmentTotal | F1: StaffMaskPolicy | G1: StaffMaskStart1 | H1: StaffMaskEnd1 | I1: StaffMaskStart2 | J1: StaffMaskEnd2 | K1: StudentMaskPolicy | L1: StudentMaskStart1 | M1: StudentMaskEnd1 | N1: StudentMaskStart2 | O1: StudentMaskEnd2 | P1: County
A2: No | B2: Austin Isd | C2: Regular local school district | D2: 4808940 | E2: 75028 | P2: =VLOOKUP(D2,schools!A:B,2,FALSE) -> TRAVIS COUNTY
A3: No | B3: Del Valle Isd | C3: Regular local school district | D3: 4816620 | E3: 10681 | P3: =VLOOKUP(D3,schools!A:B,2,FALSE) -> TRAVIS COUNTY
A4: No | B4: Eanes Isd | C4: Regular local school district | D4: 4817760 | E4: 7962 | P4: =VLOOKUP(D4,schools!A:B,2,FALSE) -> TRAVIS COUNTY
A5: No | B5: Lago Vista Isd | C5: Regular local school district | D5: 4826400 | E5: 1615 | P5: =VLOOKUP(D5,schools!A:B,2,FALSE) -> TRAVIS COUNTY
A6: No | B6: Lake Travis Isd | C6: Regular local school district | D6: 4826470 | E6: 11009 | P6: =VLOOKUP(D6,schools!A:B,2,FALSE) -> TRAVIS COUNTY
A7: No | B7: Manor Isd | C7: Regular local school district | D7: 4828890 | E7: 9296 | P7: =VLOOKUP(D7,schools!A:B,2,FALSE) -> TRAVIS COUNTY
A8: No | B8: Pflugerville Isd | C8: Regular local school district | D8: 4834830 | E8: 25551 | P8: =VLOOKUP(D8,schools!A:B,2,FALSE) -> TRAVIS COUNTY
A9: No | B9: Texas Sch For The Blind & Visually Impaired | C9: State-operated agency | D9: 4800252 | E9: 126 | F9: Required full school year | K9: Required full school year | P9: =VLOOKUP(D9,schools!A:B,2,FALSE) -> TRAVIS COUNTY
A10: No | B10: University Of Texas At Austin H S | C10: Regular local school district | D10: 4801473 | E10: 373 | F10: Required at least part of school year | K10: Required at least part of school year | P10: =VLOOKUP(D10,schools!A:B,2,FALSE) -> TRAVIS COUNTY
A11: Yes | B11: Austin Achieve Public Schools | C11: Charter agency | D11: 4801431 | E11: 2150 | F11: Required full school year | K11: Required full school year | P11: =VLOOKUP(D11,schools!A:B,2,FALSE) -> TRAVIS COUNTY
A12: Yes | B12: Austin Discovery School | C12: Charter agency | D12: 4800265 | E12: 433 | P12: =VLOOKUP(D12,schools!A:B,2,FALSE) -> TRAVIS COUNTY
A13: Yes | B13: Cedars International Academy | C13: Charter agency | D13: 4800232 | E13: 497 | F13: Required full school year | K13: Required full school year | P13: =VLOOKUP(D13,schools!A:B,2,FALSE) -> TRAVIS COUNTY
A14: Yes | B14: Chaparral Star Academy | C14: Charter agency | D14: 4800064 | E14: 367 | P14: =VLOOKUP(D14,schools!A:B,2,FALSE) -> TRAVIS COUNTY
A15: Yes | B15: Harmony Science Academy (Austin) | C15: Charter agency | D15: 4800241 | E15: 4522 | P15: =VLOOKUP(D15,schools!A:B,2,FALSE) -> TRAVIS COUNTY
A16: Yes | B16: Kipp Texas Public Schools | C16: Charter agency | D16: 4800264 | E16: 31243 | F16: Required full school year | K16: Required full school year | P16: =VLOOKUP(D16,schools!A:B,2,FALSE) -> TRAVIS COUNTY
A17: Yes | B17: Montessori For All | C17: Charter agency | D17: 4801442 | E17: 446 | F17: Required full school year | K17: Required full school year | P17: =VLOOKUP(D17,schools!A:B,2,FALSE) -> TRAVIS COUNTY
A18: Yes | B18: Nyos Charter School | C18: Charter agency | D18: 4800058 | E18: 1078 | P18: =VLOOKUP(D18,schools!A:B,2,FALSE) -> TRAVIS COUNTY
A19: Yes | B19: Promesa Public Schools | C19: Charter agency | D19: 4801414 | E19: 991 | P19: =VLOOKUP(D19,schools!A:B,2,FALSE) -> TRAVIS COUNTY
A20: Yes | B20: Texas Empowerment Academy | C20: Charter agency | D20: 4800066 | E20: 361 | P20: =VLOOKUP(D20,schools!A:B,2,FALSE) -> TRAVIS COUNTY
A21: Yes | B21: The Excel Center (For Adults) | C21: Charter agency | D21: 4801448 | E21: 839 | P21: =VLOOKUP(D21,schools!A:B,2,FALSE) -> TRAVIS COUNTY
A22: Yes | B22: University Of Texas Elementary Charter School | C22: Charter agency | D22: 4800251 | E22: 286 | P22: =VLOOKUP(D22,schools!A:B,2,FALSE) -> TRAVIS COUNTY
A23: Yes | B23: University Of Texas University Charter School | C23: Charter agency | D23: 4800071 | E23: 646 | F23: Required full school year | K23: Required full school year | P23: =VLOOKUP(D23,schools!A:B,2,FALSE) -> TRAVIS COUNTY
A24: Yes | B24: Valor Public Schools | C24: Charter agency | D24: 4801461 | E24: 1092 | P24: =VLOOKUP(D24,schools!A:B,2,FALSE) -> TRAVIS COUNTY
A25: Yes | B25: Wayside Schools | C25: Charter agency | D25: 4800044 | E25: 1872 | P25: =VLOOKUP(D25,schools!A:B,2,FALSE) -> TRAVIS COUNTY
A26: No | B26: Arlington Isd | C26: Regular local school district | D26: 4808700 | E26: 56995 | P26: =VLOOKUP(D26,schools!A:B,2,FALSE) -> TARRANT COUNTY
A27: No | B27: Azle Isd | C27: Regular local school district | D27: 4809200 | E27: 6590 | P27: =VLOOKUP(D27,schools!A:B,2,FALSE) -> TARRANT COUNTY
A28: No | B28: Birdville Isd | C28: Regular local school district | D28: 4810230 | E28: 21661 | P28: =VLOOKUP(D28,schools!A:B,2,FALSE) -> TARRANT COUNTY
A29: No | B29: Carroll Isd | C29: Regular local school district | D29: 4813020 | E29: 8328 | P29: =VLOOKUP(D29,schools!A:B,2,FALSE) -> TARRANT COUNTY
A30: No | B30: Castleberry Isd | C30: Regular local school district | D30: 4813170 | E30: 3633 | P30: =VLOOKUP(D30,schools!A:B,2,FALSE) -> TARRANT COUNTY
A31: No | B31: Crowley Isd | C31: Regular local school district | D31: 4815910 | E31: 15886 | P31: =VLOOKUP(D31,schools!A:B,2,FALSE) -> TARRANT COUNTY
A32: No | B32: Eagle Mt-Saginaw Isd | C32: Regular local school district | D32: 4817700 | E32: 21327 | F32: Required full school year | K32: Required full school year | P32: =VLOOKUP(D32,schools!A:B,2,FALSE) -> TARRANT COUNTY
A33: No | B33: Everman Isd | C33: Regular local school district | D33: 4818810 | E33: 5619 | P33: =VLOOKUP(D33,schools!A:B,2,FALSE) -> TARRANT COUNTY
A34: No | B34: Fort Worth Isd | C34: Regular local school district | D34: 4819700 | E34: 77276 | F34: Required at least part of school year | K34: Required at least part of school year | P34: =VLOOKUP(D34,schools!A:B,2,FALSE) -> TARRANT COUNTY
A35: No | B35: Grapevine-Colleyville Isd | C35: Regular local school district | D35: 4821660 | E35: 13910 | P35: =VLOOKUP(D35,schools!A:B,2,FALSE) -> TARRANT COUNTY
A36: No | B36: Hurst-Euless-Bedford Isd | C36: Regular local school district | D36: 4824060 | E36: 22971 | P36: =VLOOKUP(D36,schools!A:B,2,FALSE) -> TARRANT COUNTY
A37: No | B37: Keller Isd | C37: Regular local school district | D37: 4825260 | E37: 31935 | P37: =VLOOKUP(D37,schools!A:B,2,FALSE) -> TARRANT COUNTY
A38: No | B38: Kennedale Isd | C38: Regular local school district | D38: 4825500 | E38: 2881 | F38: Required full school year | K38: Required full school year | P38: =VLOOKUP(D38,schools!A:B,2,FALSE) -> TARRANT COUNTY
A39: No | B39: Lake Worth Isd | C39: Regular local school district | D39: 4826490 | E39: 3308 | P39: =VLOOKUP(D39,schools!A:B,2,FALSE) -> TARRANT COUNTY
A40: No | B40: Mansfield Isd | C40: Regular local school district | D40: 4828920 | E40: 35191 | P40: =VLOOKUP(D40,schools!A:B,2,FALSE) -> TARRANT COUNTY
...

Sheet schools
A1: NCES District ID | B1: County Name | C1: District Number | D1: District Name | E1: District Type
A2: 4800004 | B2: BEXAR COUNTY | C2: 15801 | D2: POR VIDA ACADEMY | E2: CHARTER
A3: 4800014 | B3: BEXAR COUNTY | C3: 15802 | D3: GEORGE GERVIN ACADEMY | E3: CHARTER
A4: 4800061 | B4: BEXAR COUNTY | C4: 15805 | D4: NEW FRONTIERS PUBLIC SCHOOLS INC | E4: CHARTER
A5: 4800062 | B5: BEXAR COUNTY | C5: 15806 | D5: LEGACY TRADITIONAL SCHOOLS - TEXAS | E5: CHARTER
A6: 4800063 | B6: BEXAR COUNTY | C6: 15807 | D6: SOUTHWEST PREPARATORY SCHOOL | E6: CHARTER
A7: 4800053 | B7: BEXAR COUNTY | C7: 15808 | D7: INSPIRE ACADEMIES | E7: CHARTER
A8: 4800077 | B8: BEXAR COUNTY | C8: 15809 | D8: BEXAR COUNTY ACADEMY | E8: CHARTER
A9: 4800059 | B9: BEXAR COUNTY | C9: 15814 | D9: POSITIVE SOLUTIONS CHARTER SCHOOL | E9: CHARTER
A10: 4800080 | B10: BEXAR COUNTY | C10: 15815 | D10: HERITAGE ACADEMY | E10: CHARTER
A11: 4800179 | B11: BEXAR COUNTY | C11: 15822 | D11: JUBILEE ACADEMIES | E11: CHARTER
A12: 4800246 | B12: BEXAR COUNTY | C12: 15825 | D12: LIGHTHOUSE PUBLIC SCHOOLS | E12: CHARTER
A13: 4800258 | B13: BEXAR COUNTY | C13: 15827 | D13: SCHOOL OF SCIENCE AND TECHNOLOGY | E13: CHARTER
... A103: 4815210 | B103: DALLAS COUNTY | C103: 57922 | D103: COPPELL ISD | E103: INDEPENDENT
B104: DENTON COUNTY | C104: 61501 | D104: UNIVERSITY OF NORTH TEXAS | E104: INDEPENDENT
A105: 4800187 | B105: DENTON COUNTY | C105: 61802 | D105: NORTH TEXAS COLLEGIATE ACADEMY | E105: CHARTER
A106: 4801420 | B106: DENTON COUNTY | C106: 61804 | D106: LEADERSHIP PREP SCHOOL | E106: CHARTER
A107: 4801456 | B107: DENTON COUNTY | C107: 61805 | D107: TRIVIUM ACADEMY | E107: CHARTER
B108: DENTON COUNTY | C108: 61806 | D108: TEXAS WORKS | E108: CHARTER
A109: 4816740 | B109: DENTON COUNTY | C109: 61901 | D109: DENTON ISD | E109: INDEPENDENT
A110: 4827300 | B110: DENTON COUNTY | C110: 61902 | D110: LEWISVILLE ISD | E110: INDEPENDENT
A111: 4834920 | B111: DENTON COUNTY | C111: 61903 | D111: PILOT POINT ISD | E111: INDEPENDENT
A112: 4825980 | B112: DENTON COUNTY | C112: 61905 | D112: KRUM ISD | E112: INDEPENDENT
A113: 4835310 | B113: DENTON COUNTY | C113: 61906 | D113: PONDER ISD | E113: INDEPENDENT
A114: 4808910 | B114: DENTON COUNTY | C114: 61907 | D114: AUBREY ISD | E114: INDEPENDENT
A115: 4839180 | B115: DENTON COUNTY | C115: 61908 | D115: SANGER ISD | E115: INDEPENDENT
A116: 4808670 | B116: DENTON COUNTY | C116: 61910 | D116: ARGYLE ISD | E116: INDEPENDENT
A117: 4833180 | B117: DENTON COUNTY | C117: 61911 | D117: NORTHWEST ISD | E117: INDEPENDENT
A118: 4826430 | B118: DENTON COUNTY | C118: 61912 | D118: LAKE DALLAS ISD | E118: INDEPENDENT
A119: 4827720 | B119: DENTON COUNTY | C119: 61914 | D119: LITTLE ELM ISD | E119: INDEPENDENT
A120: 4800037 | B120: EL PASO COUNTY | C120: 71801 | D120: BURNHAM WOOD CHARTER SCHOOL DISTRICT | E120: CHARTER
... A225: 4899131 | B225: TARRANT COUNTY | C225: 220821 | D225: ACADEMY OF VISUAL AND PERFORMING ARTS | E225: CHARTER
B226: TARRANT COUNTY | C226: 220822 | D226: NEW HEIGHTS | E226: CHARTER
B227: TARRANT COUNTY | C227: 220823 | D227: INFINITE MINDS | E227: CHARTER
A228: 4808700 | B228: TARRANT COUNTY | C228: 220901 | D228: ARLINGTON ISD | E228: INDEPENDENT
A229: 4810230 | B229: TARRANT COUNTY | C229: 220902 | D229: BIRDVILLE ISD | E229: INDEPENDENT
A230: 4818810 | B230: TARRANT COUNTY | C230: 220904 | D230: EVERMAN ISD | E230: INDEPENDENT
A231: 4819700 | B231: TARRANT COUNTY | C231: 220905 | D231: FORT WORTH ISD | E231: INDEPENDENT
A232: 4821660 | B232: TARRANT COUNTY | C232: 220906 | D232: GRAPEVINE-COLLEYVILLE ISD | E232: INDEPENDENT
A233: 4825260 | B233: TARRANT COUNTY | C233: 220907 | D233: KELLER ISD | E233: INDEPENDENT
...

Sheet notes
C5: all data rows by district
