Workbook

Sheet Sheet1
A1: County | B1: Exemption Rate
A2: Andrews | B2: =VLOOKUP(A2,Sheet2!B2:M256,12,FALSE) -> 0.01986755
A3: Atascosa | B3: =VLOOKUP(A3,Sheet2!B3:M257,12,FALSE) -> 0.0099337748
A4: Bailey | B4: =VLOOKUP(A4,Sheet2!B4:M258,12,FALSE) -> 0
A5: Bell | B5: =VLOOKUP(A5,Sheet2!B5:M259,12,FALSE) -> 0.037217545
A6: Bexar | B6: =VLOOKUP(A6,Sheet2!B6:M260,12,FALSE) -> 0.028058406
A7: Borden | B7: =VLOOKUP(A7,Sheet2!B7:M261,12,FALSE) -> 0.055555556
A8: Brazoria | B8: =VLOOKUP(A8,Sheet2!B8:M262,12,FALSE) -> 0.03229738
A9: Brewster | B9: =VLOOKUP(A9,Sheet2!B9:M263,12,FALSE) -> 0.026315789
A10: Brown | B10: =VLOOKUP(A10,Sheet2!B10:M264,12,FALSE) -> 0.063636364
A11: Carson | B11: =VLOOKUP(A11,Sheet2!B11:M265,12,FALSE) -> 0.083333333
A12: Cochran | B12: =VLOOKUP(A12,Sheet2!B12:M266,12,FALSE) -> 0.047619048
A13: Collin | B13: =VLOOKUP(A13,Sheet2!B13:M267,12,FALSE) -> 0.058071206
... A51: Yoakum | B51: =VLOOKUP(A51,Sheet2!B51:M305,12,FALSE) -> 0.058333333
A52: Texas | B52: 0.023806574

Sheet weighted average
A1: County | B1: Exemption Rate | C1: Weighted exemption rate
A2: Andrews | B2: =VLOOKUP(A2,Sheet2!B2:M256,12,FALSE) -> 0.01986755 | C2: =B2*[1]Sheet1!$B2/[1]Sheet1!$B$52 -> 1.2014818e-05
A3: Atascosa | B3: =VLOOKUP(A3,Sheet2!B3:M257,12,FALSE) -> 0.0099337748 | C3: =B3*[1]Sheet1!$B3/[1]Sheet1!$B$52 -> 1.6756808e-05
A4: Bailey | B4: =VLOOKUP(A4,Sheet2!B4:M258,12,FALSE) -> 0 | C4: =B4*[1]Sheet1!$B4/[1]Sheet1!$B$52 -> 0
A5: Bell | B5: =VLOOKUP(A5,Sheet2!B5:M259,12,FALSE) -> 0.037217545 | C5: =B5*[1]Sheet1!$B5/[1]Sheet1!$B$52 -> 0.00047526102
A6: Bexar | B6: =VLOOKUP(A6,Sheet2!B6:M260,12,FALSE) -> 0.028058406 | C6: =B6*[1]Sheet1!$B6/[1]Sheet1!$B$52 -> 0.0019079362
A7: Borden | B7: =VLOOKUP(A7,Sheet2!B7:M261,12,FALSE) -> 0.055555556 | C7: =B7*[1]Sheet1!$B7/[1]Sheet1!$B$52 -> 9.8893009e-07
A8: Brazoria | B8: =VLOOKUP(A8,Sheet2!B8:M262,12,FALSE) -> 0.03229738 | C8: =B8*[1]Sheet1!$B8/[1]Sheet1!$B$52 -> 0.00042651639
A9: Brewster | B9: =VLOOKUP(A9,Sheet2!B9:M263,12,FALSE) -> 0.026315789 | C9: =B9*[1]Sheet1!$B9/[1]Sheet1!$B$52 -> 7.996289e-06
A10: Brown | B10: =VLOOKUP(A10,Sheet2!B10:M264,12,FALSE) -> 0.063636364 | C10: =B10*[1]Sheet1!$B10/[1]Sheet1!$B$52 -> 7.8564112e-05
A11: Carson | B11: =VLOOKUP(A11,Sheet2!B11:M265,12,FALSE) -> 0.083333333 | C11: =B11*[1]Sheet1!$B11/[1]Sheet1!$B$52 -> 1.5505075e-05
A12: Cochran | B12: =VLOOKUP(A12,Sheet2!B12:M266,12,FALSE) -> 0.047619048 | C12: =B12*[1]Sheet1!$B12/[1]Sheet1!$B$52 -> 3.930864e-06
A13: Collin | B13: =VLOOKUP(A13,Sheet2!B13:M267,12,FALSE) -> 0.058071206 | C13: =B13*[1]Sheet1!$B13/[1]Sheet1!$B$52 -> 0.0023284618
... A51: Yoakum | B51: =VLOOKUP(A51,Sheet2!B51:M305,12,FALSE) -> 0.058333333 | C51: =B51*[1]Sheet1!$B51/[1]Sheet1!$B$52 -> 1.4132734e-05
A52: Texas | B52: =AVERAGE(B2:B51) -> 0.045616417 | C52: =SUM(C2:C51) -> 0.023806574

Sheet Sheet2
C1: 2013-2014 | D1: 2014-2015 | E1: 2015-2016 | F1: 2016-2017 | G1: 2017-2018 | H1: 2018-2019 | I1: 2019-2020 | J1: 2020-2021 | K1: 2021-2022 | L1: 2022-2023 | M1: 2023-2024
A2: Texas | B2: Texas | C2: 0.013455556 | D2: 0.012880717 | E2: 0.013457254 | F2: 0.015512147 | G2: 0.018047066 | H2: 0.021696385 | I2: 0.0224 | J2: 0.0214 | K2: 0.0264 | L2: 0.0324 | M2: 0.0363
A3: Counties | B3: Anderson | C3: 0.0079617834 | D3: 0.0058309038 | E3: 0.0065359477 | F3: 0.01552795 | G3: 0.013651877 | H3: 0.021487603 | I3: 0.015410959 | J3: 0.024691358 | K3: 0.032374101 | L3: 0.032315978 | M3: 0.043087971
B4: Andrews | C4: 0.0035087719 | D4: 0.0089820359 | E4: 0.013513514 | F4: 0.0097402597 | G4: 0.012195122 | H4: 0.024793388 | I4: 0.0095238095 | J4: 0.024767802 | K4: 0 | L4: 0.0063694268 | M4: 0.01986755
B5: Angelina | C5: 0.011053795 | D5: 0.0060744115 | E5: 0.016587678 | F5: 0.011764706 | G5: 0.015139442 | H5: 0.017213115 | I5: 0.01822504 | J5: 0.014787431 | K5: 0.023450586 | L5: 0.037885463 | M5: 0.051327434
B6: Aransas | C6: 0.022304833 | D6: 0.011111111 | E6: 0.014336918 | F6: 0.020833333 | G6: 0.011904762 | H6: 0.010695187 | I6: 0.025531915 | J6: 0.028735632 | K6: 0 | L6: 0.0093023256 | M6: 0.023255814
B7: Archer | C7: 0.0081300813 | D7: 0.022222222 | E7: 0 | F7: 0 | G7: 0 | H7: 0.015503876 | I7: 0.014084507 | J7: 0.0064516129 | K7: 0.025316456 | L7: 0.057971014 | M7: 0.053846154
B8: Armstrong | C8: 0 | D8: 0.037037037 | E8: 0 | F8: 0.041666667 | G8: 0 | H8: 0.032258065 | I8: 0.074074074 | J8: 0.1 | K8: 0.055555556 | L8: 0 | M8: 0.04
B9: Atascosa | C9: 0.0030959752 | D9: 0.0029806259 | E9: 0.0046801872 | F9: 0.012861736 | G9: 0.0093896714 | H9: 0.016248154 | I9: 0.0033898305 | J9: 0.016393443 | K9: 0.0048543689 | L9: 0.022123894 | M9: 0.0099337748
B10: Austin | C10: 0.011160714 | D10: 0.011210762 | E10: 0.023364486 | F10: 0.020997375 | G10: 0.016509434 | H10: 0.033942559 | I10: 0.018867925 | J10: 0.020833333 | K10: 0.014851485 | L10: 0.046997389 | M10: 0.054590571
B11: Bailey | C11: 0 | D11: 0 | E11: 0.0090909091 | F11: 0.017699115 | G11: 0.01 | H11: 0.010989011 | I11: 0.011235955 | J11: 0 | K11: 0.032258065 | L11: 0.027522936 | M11: 0
B12: Bandera | C12: 0.030769231 | D12: 0.042168675 | E12: 0.013245033 | F12: 0.053892216 | G12: 0.021126761 | H12: 0.010695187 | I12: 0.043715847 | J12: 0.033333333 | K12: 0.025316456 | L12: 0.062827225 | M12: 0.04
B13: Bastrop | C13: 0.019695613 | D13: 0.024744027 | E13: 0.016853933 | F13: 0.033737024 | G13: 0.018921476 | H13: 0.021834061 | I13: 0.027287319 | J13: 0.02047502 | K13: 0.034082107 | L13: 0.028396009 | M13: 0.032740214
B14: Baylor | C14: 0 | D14: 0.018181818 | E14: 0 | F14: 0 | G14: 0.021276596 | H14: 0.017857143 | I14: 0 | J14: 0.036363636 | K14: 0.04 | L14: 0 | M14: 0.019230769
B15: Bee | C15: 0 | D15: 0.0024630542 | E15: 0.0025839793 | F15: 0 | G15: 0 | H15: 0.0052493438 | I15: 0.0076923077 | J15: 0.0085470085 | K15: 0.010666667 | L15: 0.028846154 | M15: 0.024767802
... B52: Coryell | C52: 0.032648126 | D52: 0.042303173 | E52: 0.010088272 | F52: 0.013853904 | G52: 0.016645327 | H52: 0.027194067 | I52: 0.023030303 | J52: 0.028465347 | K52: 0.03198032 | L52: 0.031506849 | M52: 0.037234043
B53: Cottle | D53: 0 | E53: 0 | F53: 0 | G53: 0 | H53: 0 | I53: 0 | J53: 0 | K53: 0 | L53: 0 | M53: 0.11111111
B54: Crane | C54: 0 | D54: 0.011904762 | E54: 0 | F54: 0 | G54: 0 | H54: 0 | I54: 0.012345679 | J54: 0.012345679 | K54: 0.019047619 | L54: 0
B55: Crockett | C55: 0 | D55: 0.014705882 | E55: 0 | F55: 0 | G55: 0 | H55: 0.017857143 | I55: 0 | J55: 0.037735849 | K55: 0 | L55: 0 | M55: 0
B56: Crosby | C56: 0 | D56: 0.012048193 | E56: 0.010752688 | F56: 0.011363636 | G56: 0.0125 | H56: 0.028571429 | I56: 0 | J56: 0 | K56: 0.027777778 | L56: 0.016129032 | M56: 0.036363636
B57: Culberson | C57: 0 | E57: 0 | F57: 0 | G57: 0 | H57: 0 | I57: 0 | J57: 0 | K57: 0 | L57: 0.027027027 | M57: 0.038461538
B58: Dallam | C58: 0.0062111801 | D58: 0 | E58: 0.035928144 | F58: 0.018867925 | G58: 0.028901734 | H58: 0.01754386 | I58: 0.051282051 | J58: 0.011428571 | K58: 0.029411765 | L58: 0.038251366 | M58: 0.041420118
B59: Dallas | C59: 0.0083736231 | D59: 0.0089566272 | E59: 0.0084136814 | F59: 0.01156959 | G59: 0.013656483 | H59: 0.018357953 | I59: 0.019557413 | J59: 0.017307692 | K59: 0.020258132 | L59: 0.026374507 | M59: 0.026160683
B60: Dawson | C60: 0.0049751244 | D60: 0.013513514 | E60: 0.010152284 | F60: 0.015706806 | G60: 0.014423077 | H60: 0.053763441 | I60: 0.076433121 | J60: 0.033898305 | K60: 0.032258065 | L60: 0.078014184 | M60: 0.10596026
B61: Deaf Smith | C61: 0.0027027027 | D61: 0 | E61: 0 | F61: 0 | G61: 0.0033557047 | H61: 0.0091463415 | I61: 0 | J61: 0 | K61: 0 | L61: 0 | M61: 0.0064724919
B62: Delta | C62: 0 | D62: 0 | E62: 0.052631579 | F62: 0.017857143 | G62: 0 | H62: 0.018518519 | I62: 0.016949153 | J62: 0.014285714 | K62: 0 | L62: 0 | M62: 0.046153846
B63: Denton | C63: 0.092242934 | D63: 0.034033665 | E63: 0.035009085 | F63: 0.039185691 | G63: 0.047211321 | H63: 0.052968768 | I63: 0.046534438 | J63: 0.043923342 | K63: 0.05958971 | L63: 0.06102981 | M63: 0.069126378
B64: DeWitt | C64: 0 | D64: 0.0082987552 | E64: 0.015 | F64: 0.019704433 | G64: 0.0050505051 | H64: 0.0050251256 | I64: 0.0048780488 | J64: 0.021857923 | K64: 0.014925373 | L64: 0.021276596 | M64: 0.027472527
B65: Dickens | C65: 0 | D65: 0 | E65: 0 | F65: 0 | G65: 0 | H65: 0 | I65: 0 | J65: 0 | K65: 0 | L65: 0.090909091 | M65: 0.047619048
B66: Dimmit | C66: 0.0047169811 | D66: 0 | E66: 0 | F66: 0 | G66: 0 | H66: 0 | I66: 0 | J66: 0 | K66: 0 | L66: 0 | M66: 0
B67: Donley | C67: 0 | D67: 0.037735849 | E67: 0 | F67: 0.025 | G67: 0.025 | H67: 0 | I67: 0 | J67: 0.052631579 | K67: 0.085106383 | L67: 0.048780488 | M67: 0.022727273
B68: Duval | C68: 0 | D68: 0 | E68: 0 | F68: 0 | G68: 0.0053475936 | H68: 0 | I68: 0.012578616 | J68: 0.0067567568 | K68: 0.024242424 | L68: 0.013333333 | M68: 0.015625
B69: Eastland | C69: 0.022421525 | D69: 0.0087336245 | E69: 0.028037383 | F69: 0.029850746 | G69: 0.055555556 | H69: 0.049261084 | I69: 0.025125628 | J69: 0.03 | K69: 0.039408867 | L69: 0.027906977 | M69: 0.032786885
... B77: Fayette | C77: 0.0067114094 | D77: 0.0032786885 | E77: 0.010526316 | F77: 0.013245033 | G77: 0 | H77: 0.01459854 | I77: 0.014285714 | J77: 0.010676157 | K77: 0.014285714 | L77: 0.022058824 | M77: 0.017316017
B78: Fisher | C78: 0 | E78: 0 | F78: 0 | G78: 0 | H78: 0.023255814 | I78: 0 | J78: 0 | K78: 0.027027027 | L78: 0.028571429 | M78: 0.022727273
B79: Floyd | C79: 0 | D79: 0 | E79: 0.02247191 | F79: 0.011235955 | G79: 0 | H79: 0 | I79: 0 | J79: 0.0375 | K79: 0.014705882 | L79: 0 | M79: 0.048780488
B80: Foard | C80: 0 | D80: 0 | E80: 0 | F80: 0 | G80: 0 | H80: 0 | I80: 0 | J80: 0 | K80: 0 | L80: 0.066666667 | M80: 0
B81: Fort Bend | C81: 0.0094620168 | D81: 0.0082272786 | E81: 0.0081669691 | F81: 0.0093567251 | G81: 0.0097548453 | H81: 0.013597804 | I81: 0.0076757016 | J81: 0.0089115213 | K81: 0.011764706 | L81: 0.017020089 | M81: 0.018199705
B82: Franklin | C82: 0.0067567568 | D82: 0.014388489 | E82: 0.022727273 | F82: 0.024590164 | G82: 0 | H82: 0.021505376 | I82: 0.0098039216 | J82: 0 | K82: 0 | L82: 0.031578947 | M82: 0.047619048
B83: Freestone | C83: 0.017123288 | D83: 0.01509434 | E83: 0.0125 | F83: 0.019083969 | G83: 0.025531915 | H83: 0.029739777 | I83: 0.021459227 | J83: 0.048582996 | K83: 0.027777778 | L83: 0.058091286 | M83: 0.074889868
...
