Workbook

Sheet Sheet1
A1: County | B1: Kindergarten | C1: 7th Grade | D1: Average Vaccination Rate
A2: Andrews | B2: =VLOOKUP(A2,Sheet2!A2:B256,2,FALSE) -> 0.95470383 | C2: =VLOOKUP(A2,Sheet3!A:B,2,FALSE) -> 0.97846154 | D2: =AVERAGE(B2:C2) -> 0.96658269
A3: Atascosa | B3: =VLOOKUP(A3,Sheet2!A3:B257,2,FALSE) -> 0.96141975 | C3: =VLOOKUP(A3,Sheet3!A:B,2,FALSE) -> 0.98509687 | D3: =AVERAGE(B3:C3) -> 0.97325831
A4: Bailey | B4: =VLOOKUP(A4,Sheet2!A4:B258,2,FALSE) -> 0.96261682 | C4: =VLOOKUP(A4,Sheet3!A:B,2,FALSE) -> 1 | D4: =AVERAGE(B4:C4) -> 0.98130841
A5: Bell | B5: =VLOOKUP(A5,Sheet2!A5:B259,2,FALSE) -> 0.95126114 | C5: =VLOOKUP(A5,Sheet3!A:B,2,FALSE) -> 0.97274401 | D5: =AVERAGE(B5:C5) -> 0.96200258
A6: Bexar | B6: =VLOOKUP(A6,Sheet2!A6:B260,2,FALSE) -> 0.94745076 | C6: =VLOOKUP(A6,Sheet3!A:B,2,FALSE) -> 0.97716485 | D6: =AVERAGE(B6:C6) -> 0.96230781
A7: Borden | B7: =VLOOKUP(A7,Sheet2!A7:B261,2,FALSE) -> 0.88235294 | C7: =VLOOKUP(A7,Sheet3!A:B,2,FALSE) -> 0.90909091 | D7: =AVERAGE(B7:C7) -> 0.89572193
A8: Brazoria | B8: =VLOOKUP(A8,Sheet2!A8:B262,2,FALSE) -> 0.96212748 | C8: =VLOOKUP(A8,Sheet3!A:B,2,FALSE) -> 0.9853684 | D8: =AVERAGE(B8:C8) -> 0.97374794
A9: Brewster | B9: =VLOOKUP(A9,Sheet2!A9:B263,2,FALSE) -> 0.83950617 | C9: =VLOOKUP(A9,Sheet3!A:B,2,FALSE) -> 0.91578947 | D9: =AVERAGE(B9:C9) -> 0.87764782
A10: Brown | B10: =VLOOKUP(A10,Sheet2!A10:B264,2,FALSE) -> 0.96 | C10: =VLOOKUP(A10,Sheet3!A:B,2,FALSE) -> 0.97613883 | D10: =AVERAGE(B10:C10) -> 0.96806941
A11: Carson | B11: =VLOOKUP(A11,Sheet2!A11:B265,2,FALSE) -> 0.91954023 | C11: =VLOOKUP(A11,Sheet3!A:B,2,FALSE) -> 0.93243243 | D11: =AVERAGE(B11:C11) -> 0.92598633
A12: Cochran | B12: =VLOOKUP(A12,Sheet2!A12:B266,2,FALSE) -> 0.92682927 | C12: =VLOOKUP(A12,Sheet3!A:B,2,FALSE) -> 1 | D12: =AVERAGE(B12:C12) -> 0.96341463
A13: Collin | B13: =VLOOKUP(A13,Sheet2!A13:B267,2,FALSE) -> 0.93042341 | C13: =VLOOKUP(A13,Sheet3!A:B,2,FALSE) -> 0.96646282 | D13: =AVERAGE(B13:C13) -> 0.94844311
... A51: Yoakum | B51: =VLOOKUP(A51,Sheet2!A51:B305,2,FALSE) -> 0.94615385 | C51: =VLOOKUP(A51,Sheet3!A:B,2,FALSE) -> 1 | D51: =AVERAGE(B51:C51) -> 0.97307692

Sheet Sheet1 (2)
A1: County | B1: Kindergarten | C1: 7th Grade | D1: Average Vaccination Rate | E1: Vacc Rate + Exemption | F1: proj unvaccinated
A2: Andrews | B2: =VLOOKUP(A2,Sheet2!A2:B256,2,FALSE) -> 0.95470383 | C2: =VLOOKUP(A2,Sheet3!A:B,2,FALSE) -> 0.97846154 | D2: =AVERAGE(B2:C2) -> 0.96658269 | E2: =D2+[1]Sheet1!$B$2 -> 0.98648269 | F2: =1-E2 -> 0.013517314
A3: Atascosa | B3: =VLOOKUP(A3,Sheet2!A3:B257,2,FALSE) -> 0.96141975 | C3: =VLOOKUP(A3,Sheet3!A:B,2,FALSE) -> 0.98509687 | D3: =AVERAGE(B3:C3) -> 0.97325831 | E3: =D3+[1]Sheet1!$B$2 -> 0.99315831 | F3: =1-E3 -> 0.0068416883
A4: Bailey | B4: =VLOOKUP(A4,Sheet2!A4:B258,2,FALSE) -> 0.96261682 | C4: =VLOOKUP(A4,Sheet3!A:B,2,FALSE) -> 1 | D4: =AVERAGE(B4:C4) -> 0.98130841 | E4: =D4+[1]Sheet1!$B$2 -> 1.0012084 | F4: =1-E4 -> -0.0012084112
A5: Bell | B5: =VLOOKUP(A5,Sheet2!A5:B259,2,FALSE) -> 0.95126114 | C5: =VLOOKUP(A5,Sheet3!A:B,2,FALSE) -> 0.97274401 | D5: =AVERAGE(B5:C5) -> 0.96200258 | E5: =D5+[1]Sheet1!$B$2 -> 0.98190258 | F5: =1-E5 -> 0.018097422
A6: Bexar | B6: =VLOOKUP(A6,Sheet2!A6:B260,2,FALSE) -> 0.94745076 | C6: =VLOOKUP(A6,Sheet3!A:B,2,FALSE) -> 0.97716485 | D6: =AVERAGE(B6:C6) -> 0.96230781 | E6: =D6+[1]Sheet1!$B$2 -> 0.98220781 | F6: =1-E6 -> 0.017792193
A7: Borden | B7: =VLOOKUP(A7,Sheet2!A7:B261,2,FALSE) -> 0.88235294 | C7: =VLOOKUP(A7,Sheet3!A:B,2,FALSE) -> 0.90909091 | D7: =AVERAGE(B7:C7) -> 0.89572193 | E7: =D7+[1]Sheet1!$B$2 -> 0.91562193 | F7: =1-E7 -> 0.084378075
A8: Brazoria | B8: =VLOOKUP(A8,Sheet2!A8:B262,2,FALSE) -> 0.96212748 | C8: =VLOOKUP(A8,Sheet3!A:B,2,FALSE) -> 0.9853684 | D8: =AVERAGE(B8:C8) -> 0.97374794 | E8: =D8+[1]Sheet1!$B$2 -> 0.99364794 | F8: =1-E8 -> 0.0063520569
A9: Brewster | B9: =VLOOKUP(A9,Sheet2!A9:B263,2,FALSE) -> 0.83950617 | C9: =VLOOKUP(A9,Sheet3!A:B,2,FALSE) -> 0.91578947 | D9: =AVERAGE(B9:C9) -> 0.87764782 | E9: =D9+[1]Sheet1!$B$2 -> 0.89754782 | F9: =1-E9 -> 0.10245218
A10: Brown | B10: =VLOOKUP(A10,Sheet2!A10:B264,2,FALSE) -> 0.96 | C10: =VLOOKUP(A10,Sheet3!A:B,2,FALSE) -> 0.97613883 | D10: =AVERAGE(B10:C10) -> 0.96806941 | E10: =D10+[1]Sheet1!$B$2 -> 0.98796941 | F10: =1-E10 -> 0.012030586
A11: Carson | B11: =VLOOKUP(A11,Sheet2!A11:B265,2,FALSE) -> 0.91954023 | C11: =VLOOKUP(A11,Sheet3!A:B,2,FALSE) -> 0.93243243 | D11: =AVERAGE(B11:C11) -> 0.92598633 | E11: =D11+[1]Sheet1!$B$2 -> 0.94588633 | F11: =1-E11 -> 0.054113669
A12: Cochran | B12: =VLOOKUP(A12,Sheet2!A12:B266,2,FALSE) -> 0.92682927 | C12: =VLOOKUP(A12,Sheet3!A:B,2,FALSE) -> 1 | D12: =AVERAGE(B12:C12) -> 0.96341463 | E12: =D12+[1]Sheet1!$B$2 -> 0.98331463 | F12: =1-E12 -> 0.016685366
A13: Collin | B13: =VLOOKUP(A13,Sheet2!A13:B267,2,FALSE) -> 0.93042341 | C13: =VLOOKUP(A13,Sheet3!A:B,2,FALSE) -> 0.96646282 | D13: =AVERAGE(B13:C13) -> 0.94844311 | E13: =D13+[1]Sheet1!$B$2 -> 0.96834311 | F13: =1-E13 -> 0.031656885
... A51: Yoakum | B51: =VLOOKUP(A51,Sheet2!A51:B305,2,FALSE) -> 0.94615385 | C51: =VLOOKUP(A51,Sheet3!A:B,2,FALSE) -> 1 | D51: =AVERAGE(B51:C51) -> 0.97307692 | E51: =D51+[1]Sheet1!$B$2 -> 0.99297692 | F51: =1-E51 -> 0.0070230769

Sheet Sheet3
A1: Anderson | B1: 0.97321429
A2: Andrews | B2: 0.97846154
A3: Angelina | B3: 0.97545008
A4: Aransas | B4: 0.97727273
A5: Archer | B5: 0.98148148
A6: Armstrong | B6: 0.95238095
A7: Atascosa | B7: 0.98509687
A8: Austin | B8: 0.96007984
A9: Bailey | B9: 1
A10: Bandera | B10: 0.97382199
A11: Bastrop | B11: 0.98007968
A12: Baylor | B12: 0.97777778
... A130: Kendall | B130: 0.94346617
A131: Kenedy | B131: NR
A132: Kent | B132: 1
A133: Kerr | B133: 0.97160243
A134: Kimble | B134: 0.92857143
A135: King | B135: 0.91666667
A136: Kinney | B136: 1
A137: Kleberg | B137: 0.99376947
A138: Knox | B138: 1
A139: La Salle | B139: 1
A140: Lamar | B140: 0.97568389
A141: Lamb | B141: 0.98584906
A142: Lampasas | B142: 0.98293515
A143: Lavaca | B143: 0.9628483
... A150: Llano | B150: 0.97709924
A151: Loving | B151: NR
A152: Lubbock | B152: 0.97000522
A153: Lynn | B153: 0.89393939
A154: Madison | B154: 0.98395722
A155: Marion | B155: 0.97647059
A156: Martin | B156: 0.96153846
A157: Mason | B157: 1
A158: Matagorda | B158: 0.96435272
A159: Maverick | B159: 0.99236641
A160: Mcculloch | B160: 1
A161: Mclennan | B161: 0.97571795
A162: Mcmullen | B162: 0.91304348
A163: Medina | B163: 0.98289829
...

Sheet Sheet2
A1: County | B1: MMR
A2: Anderson | B2: 0.94785847
A3: Andrews | B3: 0.95470383
A4: Angelina | B4: 0.93866171
A5: Aransas | B5: 0.9726776
A6: Archer | B6: 0.94964029
A7: Armstrong | B7: 0.92307692
A8: Atascosa | B8: 0.96141975
A9: Austin | B9: 0.94776119
A10: Bailey | B10: 0.96261682
A11: Bandera | B11: 0.93478261
A12: Bastrop | B12: 0.95460993
A13: Baylor | B13: 0.975
... A151: Llano | B151: 0.89552239
A152: Loving | B152: NR
A153: Lubbock | B153: 0.91341077
A154: Lynn | B154: 0.91304348
A155: Madison | B155: 0.96571429
A156: Marion | B156: 0.98591549
A157: Martin | B157: 0.92957746
A158: Mason | B158: 0.92307692
A159: Matagorda | B159: 0.96969697
A160: Maverick | B160: 0.93942505
A161: Mcculloch | B161: 0.93975904
A162: Mclennan | B162: 0.95281816
A163: Mcmullen | B163: 0.9375
A164: Medina | B164: 0.96653543
... A256: Texas | B256: 0.93242125
